Workbook

Sheet Microcode
A1: Line | B1: Microcode Word | C1: Activation Line | D1: Signals | E1: Cont | F1: Souce1 | G1: Dest1 | H1: Source2 | I1: D2 | J1: F | K1: W | L1: E | M1: Type | N1: ALUop | O1: Tmp | P1: R | Q1: Jcond | R1: JmpT | S1: IC | T1: EC | U1: SR | W1: Arch | X1: Operation | AD1: Opcodes
A2: =DEC2HEX(ROW(A1)-ROW($A$1),3) -> 000 | B2: 01100100101000110001101001111 | C2: 00?.00???0??.00 | D2: 00? | E2: 00 | F2: {=INDEX(Sources!A:A, 1 + BIN2DEC(LEFT($B2,5)))} -> OPR | G2: {=INDEX(Dest1!A:A,1+BIN2DEC(MID($B2,6,5)))} -> TMPA | H2: {=INDEX(Source2!A:A,1+BIN2DEC(MID($B2,11,4)))} -> 8 | I2: {=INDEX('D2'!A:A,1+BIN2DEC(MID($B2,16,2)))} -> TMPB | J2: =BIN2DEC(MID($B2,17,1)) -> 0 | K2: =BIN2DEC(MID($B2,18,1)) -> 0 | L2: =BIN2DEC(MID($B2,19,1)) -> 0 | M2: {=INDEX(Types!A:A,1+BIN2DEC(MID($B2,20,2)))} -> ALU | N2: {=IF(M2="ALU",INDEX(ALUOps!A:A,1+BIN2DEC(MID($B2,22,5))),"")} -> 9 | O2: {=IF(M2="ALU",INDEX(TMP!A:A,1+BIN2DEC(MID($B2,27,2))),"")} -> 3 | P2: =IF(M2="ALU",BIN2DEC(MID($B2,29,1)),"") -> 1 | Q2: =IF(M2="Jump",BIN2DEC(MID($B2,22,4)),"") | R2: =IF(M2="Jump",15-BIN2DEC(MID($B2,26,4)),"") | S2: {=IF(M2="Control",INDEX(IC!A:A,1+BIN2DEC(MID($B2,21,4))),"")} | T2: {=IF(M2="Control",INDEX(EC!A:A,1+BIN2DEC(MID($B2,25,3))),"")} | U2: {=IF(M2="Control",INDEX(SR!A:A,1+BIN2DEC(MID($B2,28,2))),"")} | X2: alu rm<->r | AD2: 00,01,02,03,08,09,0a,0b,10,11,12,13,18,19,1a,1b,20,21,22,23,28,29,2a,2b,30,31,32,33,38,39,3a,3b
A3: =DEC2HEX(ROW(A2)-ROW($A$1),3) -> 001 | B3: 01011011000000000110000000100 | F3: {=INDEX(Sources!A:A, 1 + BIN2DEC(LEFT($B3,5)))} -> SIGMA | G3: {=INDEX(Dest1!A:A,1+BIN2DEC(MID($B3,6,5)))} -> OPR | H3: {=INDEX(Source2!A:A,1+BIN2DEC(MID($B3,11,4)))} -> -- | I3: {=INDEX('D2'!A:A,1+BIN2DEC(MID($B3,16,2)))} -> 0 | J3: =BIN2DEC(MID($B3,17,1)) -> 0 | K3: =BIN2DEC(MID($B3,18,1)) -> 1 | L3: =BIN2DEC(MID($B3,19,1)) -> 1 | M3: {=INDEX(Types!A:A,1+BIN2DEC(MID($B3,20,2)))} -> Control | N3: {=IF(M3="ALU",INDEX(ALUOps!A:A,1+BIN2DEC(MID($B3,22,5))),"")} | O3: {=IF(M3="ALU",INDEX(TMP!A:A,1+BIN2DEC(MID($B3,27,2))),"")} | P3: =IF(M3="ALU",BIN2DEC(MID($B3,29,1)),"") | Q3: =IF(M3="Jump",BIN2DEC(MID($B3,22,4)),"") | R3: =IF(M3="Jump",15-BIN2DEC(MID($B3,26,4)),"") | S3: {=IF(M3="Control",INDEX(IC!A:A,1+BIN2DEC(MID($B3,21,4))),"")} -> 0 | T3: {=IF(M3="Control",INDEX(EC!A:A,1+BIN2DEC(MID($B3,25,3))),"")} -> 1 | U3: {=IF(M3="Control",INDEX(SR!A:A,1+BIN2DEC(MID($B3,28,2))),"")} -> 0
A4: =DEC2HEX(ROW(A3)-ROW($A$1),3) -> 002 | B4: 00000000000000000000000000000 | G4: {=INDEX(Dest1!A:A,1+BIN2DEC(MID($B4,6,5)))} -> -- | H4: {=INDEX(Source2!A:A,1+BIN2DEC(MID($B4,11,4)))} -> -- | N4: {=IF(M4="ALU",INDEX(ALUOps!A:A,1+BIN2DEC(MID($B4,22,5))),"")} | O4: {=IF(M4="ALU",INDEX(TMP!A:A,1+BIN2DEC(MID($B4,27,2))),"")} | P4: =IF(M4="ALU",BIN2DEC(MID($B4,29,1)),"") | Q4: =IF(M4="Jump",BIN2DEC(MID($B4,22,4)),"") | R4: =IF(M4="Jump",15-BIN2DEC(MID($B4,26,4)),"") | S4: {=IF(M4="Control",INDEX(IC!A:A,1+BIN2DEC(MID($B4,21,4))),"")} | T4: {=IF(M4="Control",INDEX(EC!A:A,1+BIN2DEC(MID($B4,25,3))),"")} | U4: {=IF(M4="Control",INDEX(SR!A:A,1+BIN2DEC(MID($B4,28,2))),"")}
A5: =DEC2HEX(ROW(A4)-ROW($A$1),3) -> 003 | B5: 00000000000000000000000000000 | G5: {=INDEX(Dest1!A:A,1+BIN2DEC(MID($B5,6,5)))} -> -- | H5: {=INDEX(Source2!A:A,1+BIN2DEC(MID($B5,11,4)))} -> -- | N5: {=IF(M5="ALU",INDEX(ALUOps!A:A,1+BIN2DEC(MID($B5,22,5))),"")} | O5: {=IF(M5="ALU",INDEX(TMP!A:A,1+BIN2DEC(MID($B5,27,2))),"")} | P5: =IF(M5="ALU",BIN2DEC(MID($B5,29,1)),"") | Q5: =IF(M5="Jump",BIN2DEC(MID($B5,22,4)),"") | R5: =IF(M5="Jump",15-BIN2DEC(MID($B5,26,4)),"") | S5: {=IF(M5="Control",INDEX(IC!A:A,1+BIN2DEC(MID($B5,21,4))),"")} | T5: {=IF(M5="Control",INDEX(EC!A:A,1+BIN2DEC(MID($B5,25,3))),"")} | U5: {=IF(M5="Control",INDEX(SR!A:A,1+BIN2DEC(MID($B5,28,2))),"")}
A6: =DEC2HEX(ROW(A5)-ROW($A$1),3) -> 004 | B6: 01100100101010110001010001101 | C6: 00?.00???10?.00 | D6: 00? | E6: 00 | F6: {=INDEX(Sources!A:A, 1 + BIN2DEC(LEFT($B6,5)))} -> OPR | G6: {=INDEX(Dest1!A:A,1+BIN2DEC(MID($B6,6,5)))} -> TMPA | H6: {=INDEX(Source2!A:A,1+BIN2DEC(MID($B6,11,4)))} -> Q | I6: {=INDEX('D2'!A:A,1+BIN2DEC(MID($B6,16,2)))} -> TMPB | J6: =BIN2DEC(MID($B6,17,1)) -> 0 | K6: =BIN2DEC(MID($B6,18,1)) -> 0 | L6: =BIN2DEC(MID($B6,19,1)) -> 0 | M6: {=INDEX(Types!A:A,1+BIN2DEC(MID($B6,20,2)))} -> Jump | N6: {=IF(M6="ALU",INDEX(ALUOps!A:A,1+BIN2DEC(MID($B6,22,5))),"")} | O6: {=IF(M6="ALU",INDEX(TMP!A:A,1+BIN2DEC(MID($B6,27,2))),"")} | P6: =IF(M6="ALU",BIN2DEC(MID($B6,29,1)),"") | Q6: =IF(M6="Jump",BIN2DEC(MID($B6,22,4)),"") -> 8 | R6: =IF(M6="Jump",15-BIN2DEC(MID($B6,26,4)),"") -> 2 | S6: {=IF(M6="Control",INDEX(IC!A:A,1+BIN2DEC(MID($B6,21,4))),"")} | T6: {=IF(M6="Control",INDEX(EC!A:A,1+BIN2DEC(MID($B6,25,3))),"")} | U6: {=IF(M6="Control",INDEX(SR!A:A,1+BIN2DEC(MID($B6,28,2))),"")} | X6: alu A,i | AD6: 04,05,0c,0d,14,15,1c,1d,24,25,2c,2d,34,35,3c,3d
A7: =DEC2HEX(ROW(A6)-ROW($A$1),3) -> 005 | B7: 11000010010000000000000000000 | F7: {=INDEX(Sources!A:A, 1 + BIN2DEC(LEFT($B7,5)))} -> Q | G7: {=INDEX(Dest1!A:A,1+BIN2DEC(MID($B7,6,5)))} -> UNK9 | H7: {=INDEX(Source2!A:A,1+BIN2DEC(MID($B7,11,4)))} -> -- | I7: {=INDEX('D2'!A:A,1+BIN2DEC(MID($B7,16,2)))} -> 0 | J7: =BIN2DEC(MID($B7,17,1)) -> 0 | K7: =BIN2DEC(MID($B7,18,1)) -> 0 | L7: =BIN2DEC(MID($B7,19,1)) -> 0 | M7: {=INDEX(Types!A:A,1+BIN2DEC(MID($B7,20,2)))} -> Control | N7: {=IF(M7="ALU",INDEX(ALUOps!A:A,1+BIN2DEC(MID($B7,22,5))),"")} | O7: {=IF(M7="ALU",INDEX(TMP!A:A,1+BIN2DEC(MID($B7,27,2))),"")} | P7: =IF(M7="ALU",BIN2DEC(MID($B7,29,1)),"") | Q7: =IF(M7="Jump",BIN2DEC(MID($B7,22,4)),"") | R7: =IF(M7="Jump",15-BIN2DEC(MID($B7,26,4)),"") | S7: {=IF(M7="Control",INDEX(IC!A:A,1+BIN2DEC(MID($B7,21,4))),"")} -> 0 | T7: {=IF(M7="Control",INDEX(EC!A:A,1+BIN2DEC(MID($B7,25,3))),"")} -> 0 | U7: {=IF(M7="Control",INDEX(SR!A:A,1+BIN2DEC(MID($B7,28,2))),"")} -> 0
A8: =DEC2HEX(ROW(A7)-ROW($A$1),3) -> 006 | B8: 00000000000000000011101001111 | F8: {=INDEX(Sources!A:A, 1 + BIN2DEC(LEFT($B8,5)))} -> -- | G8: {=INDEX(Dest1!A:A,1+BIN2DEC(MID($B8,6,5)))} -> -- | H8: {=INDEX(Source2!A:A,1+BIN2DEC(MID($B8,11,4)))} -> -- | I8: {=INDEX('D2'!A:A,1+BIN2DEC(MID($B8,16,2)))} -> 0 | J8: =BIN2DEC(MID($B8,17,1)) -> 0 | K8: =BIN2DEC(MID($B8,18,1)) -> 0 | L8: =BIN2DEC(MID($B8,19,1)) -> 1 | M8: {=INDEX(Types!A:A,1+BIN2DEC(MID($B8,20,2)))} -> ALU | N8: {=IF(M8="ALU",INDEX(ALUOps!A:A,1+BIN2DEC(MID($B8,22,5))),"")} -> 9 | O8: {=IF(M8="ALU",INDEX(TMP!A:A,1+BIN2DEC(MID($B8,27,2))),"")} -> 3 | P8: =IF(M8="ALU",BIN2DEC(MID($B8,29,1)),"") -> 1 | Q8: =IF(M8="Jump",BIN2DEC(MID($B8,22,4)),"") | R8: =IF(M8="Jump",15-BIN2DEC(MID($B8,26,4)),"") | S8: {=IF(M8="Control",INDEX(IC!A:A,1+BIN2DEC(MID($B8,21,4))),"")} | T8: {=IF(M8="Control",INDEX(EC!A:A,1+BIN2DEC(MID($B8,25,3))),"")} | U8: {=IF(M8="Control",INDEX(SR!A:A,1+BIN2DEC(MID($B8,28,2))),"")}
A9: =DEC2HEX(ROW(A8)-ROW($A$1),3) -> 007 | B9: 01011011000000000100000000000 | F9: {=INDEX(Sources!A:A, 1 + BIN2DEC(LEFT($B9,5)))} -> SIGMA | G9: {=INDEX(Dest1!A:A,1+BIN2DEC(MID($B9,6,5)))} -> OPR | H9: {=INDEX(Source2!A:A,1+BIN2DEC(MID($B9,11,4)))} -> -- | I9: {=INDEX('D2'!A:A,1+BIN2DEC(MID($B9,16,2)))} -> 0 | J9: =BIN2DEC(MID($B9,17,1)) -> 0 | K9: =BIN2DEC(MID($B9,18,1)) -> 1 | L9: =BIN2DEC(MID($B9,19,1)) -> 0 | M9: {=INDEX(Types!A:A,1+BIN2DEC(MID($B9,20,2)))} -> Control | N9: {=IF(M9="ALU",INDEX(ALUOps!A:A,1+BIN2DEC(MID($B9,22,5))),"")} | O9: {=IF(M9="ALU",INDEX(TMP!A:A,1+BIN2DEC(MID($B9,27,2))),"")} | P9: =IF(M9="ALU",BIN2DEC(MID($B9,29,1)),"") | Q9: =IF(M9="Jump",BIN2DEC(MID($B9,22,4)),"") | R9: =IF(M9="Jump",15-BIN2DEC(MID($B9,26,4)),"") | S9: {=IF(M9="Control",INDEX(IC!A:A,1+BIN2DEC(MID($B9,21,4))),"")} -> 0 | T9: {=IF(M9="Control",INDEX(EC!A:A,1+BIN2DEC(MID($B9,25,3))),"")} -> 0 | U9: {=IF(M9="Control",INDEX(SR!A:A,1+BIN2DEC(MID($B9,28,2))),"")} -> 0
A10: =DEC2HEX(ROW(A9)-ROW($A$1),3) -> 008 | B10: 00011110100000000000000011001 | C10: 00?.000??111.00 | D10: 00? | E10: 00 | F10: {=INDEX(Sources!A:A, 1 + BIN2DEC(LEFT($B10,5)))} -> SP | G10: {=INDEX(Dest1!A:A,1+BIN2DEC(MID($B10,6,5)))} -> UNK26 | H10: {=INDEX(Source2!A:A,1+BIN2DEC(MID($B10,11,4)))} -> -- | I10: {=INDEX('D2'!A:A,1+BIN2DEC(MID($B10,16,2)))} -> 0 | J10: =BIN2DEC(MID($B10,17,1)) -> 0 | K10: =BIN2DEC(MID($B10,18,1)) -> 0 | L10: =BIN2DEC(MID($B10,19,1)) -> 0 | M10: {=INDEX(Types!A:A,1+BIN2DEC(MID($B10,20,2)))} -> Control | N10: {=IF(M10="ALU",INDEX(ALUOps!A:A,1+BIN2DEC(MID($B10,22,5))),"")} | O10: {=IF(M10="ALU",INDEX(TMP!A:A,1+BIN2DEC(MID($B10,27,2))),"")} | P10: =IF(M10="ALU",BIN2DEC(MID($B10,29,1)),"") | Q10: =IF(M10="Jump",BIN2DEC(MID($B10,22,4)),"") | R10: =IF(M10="Jump",15-BIN2DEC(MID($B10,26,4)),"") | S10: {=IF(M10="Control",INDEX(IC!A:A,1+BIN2DEC(MID($B10,21,4))),"")} -> 0 | T10: {=IF(M10="Control",INDEX(EC!A:A,1+BIN2DEC(MID($B10,25,3))),"")} -> 6 | U10: {=IF(M10="Control",INDEX(SR!A:A,1+BIN2DEC(MID($B10,28,2))),"")} -> 1 | X10: POP sr | AC10: 07,0f,17,1f | AD10: 07,0f,17,1f
A11: =DEC2HEX(ROW(A10)-ROW($A$1),3) -> 009 | B11: 00011100100000000001100011101 | F11: {=INDEX(Sources!A:A, 1 + BIN2DEC(LEFT($B11,5)))} -> SP | G11: {=INDEX(Dest1!A:A,1+BIN2DEC(MID($B11,6,5)))} -> TMPA | H11: {=INDEX(Source2!A:A,1+BIN2DEC(MID($B11,11,4)))} -> -- | I11: {=INDEX('D2'!A:A,1+BIN2DEC(MID($B11,16,2)))} -> 0 | J11: =BIN2DEC(MID($B11,17,1)) -> 0 | K11: =BIN2DEC(MID($B11,18,1)) -> 0 | L11: =BIN2DEC(MID($B11,19,1)) -> 0 | M11: {=INDEX(Types!A:A,1+BIN2DEC(MID($B11,20,2)))} -> ALU | N11: {=IF(M11="ALU",INDEX(ALUOps!A:A,1+BIN2DEC(MID($B11,22,5))),"")} -> 3 | O11: {=IF(M11="ALU",INDEX(TMP!A:A,1+BIN2DEC(MID($B11,27,2))),"")} -> 2 | P11: =IF(M11="ALU",BIN2DEC(MID($B11,29,1)),"") -> 1 | Q11: =IF(M11="Jump",BIN2DEC(MID($B11,22,4)),"") | R11: =IF(M11="Jump",15-BIN2DEC(MID($B11,26,4)),"") | S11: {=IF(M11="Control",INDEX(IC!A:A,1+BIN2DEC(MID($B11,21,4))),"")} | T11: {=IF(M11="Control",INDEX(EC!A:A,1+BIN2DEC(MID($B11,25,3))),"")} | U11: {=IF(M11="Control",INDEX(SR!A:A,1+BIN2DEC(MID($B11,28,2))),"")}
A12: =DEC2HEX(ROW(A11)-ROW($A$1),3) -> 00A | B12: 01011000110000000000000000000 | F12: {=INDEX(Sources!A:A, 1 + BIN2DEC(LEFT($B12,5)))} -> SIGMA | G12: {=INDEX(Dest1!A:A,1+BIN2DEC(MID($B12,6,5)))} -> SP | H12: {=INDEX(Source2!A:A,1+BIN2DEC(MID($B12,11,4)))} -> -- | I12: {=INDEX('D2'!A:A,1+BIN2DEC(MID($B12,16,2)))} -> 0 | J12: =BIN2DEC(MID($B12,17,1)) -> 0 | K12: =BIN2DEC(MID($B12,18,1)) -> 0 | L12: =BIN2DEC(MID($B12,19,1)) -> 0 | M12: {=INDEX(Types!A:A,1+BIN2DEC(MID($B12,20,2)))} -> Control | N12: {=IF(M12="ALU",INDEX(ALUOps!A:A,1+BIN2DEC(MID($B12,22,5))),"")} | O12: {=IF(M12="ALU",INDEX(TMP!A:A,1+BIN2DEC(MID($B12,27,2))),"")} | P12: =IF(M12="ALU",BIN2DEC(MID($B12,29,1)),"") | Q12: =IF(M12="Jump",BIN2DEC(MID($B12,22,4)),"") | R12: =IF(M12="Jump",15-BIN2DEC(MID($B12,26,4)),"") | S12: {=IF(M12="Control",INDEX(IC!A:A,1+BIN2DEC(MID($B12,21,4))),"")} -> 0 | T12: {=IF(M12="Control",INDEX(EC!A:A,1+BIN2DEC(MID($B12,25,3))),"")} -> 0 | U12: {=IF(M12="Control",INDEX(SR!A:A,1+BIN2DEC(MID($B12,28,2))),"")} -> 0
A13: =DEC2HEX(ROW(A12)-ROW($A$1),3) -> 00B | B13: 11001011010000001010000000000 | F13: {=INDEX(Sources!A:A, 1 + BIN2DEC(LEFT($B13,5)))} -> OUT | G13: {=INDEX(Dest1!A:A,1+BIN2DEC(MID($B13,6,5)))} -> REG | H13: {=INDEX(Source2!A:A,1+BIN2DEC(MID($B13,11,4)))} -> -- | I13: {=INDEX('D2'!A:A,1+BIN2DEC(MID($B13,16,2)))} -> 1 | J13: =BIN2DEC(MID($B13,17,1)) -> 1 | K13: =BIN2DEC(MID($B13,18,1)) -> 0 | L13: =BIN2DEC(MID($B13,19,1)) -> 1 | M13: {=INDEX(Types!A:A,1+BIN2DEC(MID($B13,20,2)))} -> Control | N13: {=IF(M13="ALU",INDEX(ALUOps!A:A,1+BIN2DEC(MID($B13,22,5))),"")} | O13: {=IF(M13="ALU",INDEX(TMP!A:A,1+BIN2DEC(MID($B13,27,2))),"")} | P13: =IF(M13="ALU",BIN2DEC(MID($B13,29,1)),"") | Q13: =IF(M13="Jump",BIN2DEC(MID($B13,22,4)),"") | R13: =IF(M13="Jump",15-BIN2DEC(MID($B13,26,4)),"") | S13: {=IF(M13="Control",INDEX(IC!A:A,1+BIN2DEC(MID($B13,21,4))),"")} -> 0 | T13: {=IF(M13="Control",INDEX(EC!A:A,1+BIN2DEC(MID($B13,25,3))),"")} -> 0 | U13: {=IF(M13="Control",INDEX(SR!A:A,1+BIN2DEC(MID($B13,28,2))),"")} -> 0
A14: =DEC2HEX(ROW(A13)-ROW($A$1),3) -> 00C | B14: 00011100100000000001100010101 | C14: 00?.000??110.00 | D14: 00? | E14: 00 | F14: {=INDEX(Sources!A:A, 1 + BIN2DEC(LEFT($B14,5)))} -> SP | G14: {=INDEX(Dest1!A:A,1+BIN2DEC(MID($B14,6,5)))} -> TMPA | H14: {=INDEX(Source2!A:A,1+BIN2DEC(MID($B14,11,4)))} -> -- | I14: {=INDEX('D2'!A:A,1+BIN2DEC(MID($B14,16,2)))} -> 0 | J14: =BIN2DEC(MID($B14,17,1)) -> 0 | K14: =BIN2DEC(MID($B14,18,1)) -> 0 | L14: =BIN2DEC(MID($B14,19,1)) -> 0 | M14: {=INDEX(Types!A:A,1+BIN2DEC(MID($B14,20,2)))} -> ALU | N14: {=IF(M14="ALU",INDEX(ALUOps!A:A,1+BIN2DEC(MID($B14,22,5))),"")} -> 2 | O14: {=IF(M14="ALU",INDEX(TMP!A:A,1+BIN2DEC(MID($B14,27,2))),"")} -> 2 | P14: =IF(M14="ALU",BIN2DEC(MID($B14,29,1)),"") -> 1 | Q14: =IF(M14="Jump",BIN2DEC(MID($B14,22,4)),"") | R14: =IF(M14="Jump",15-BIN2DEC(MID($B14,26,4)),"") | S14: {=IF(M14="Control",INDEX(IC!A:A,1+BIN2DEC(MID($B14,21,4))),"")} | T14: {=IF(M14="Control",INDEX(EC!A:A,1+BIN2DEC(MID($B14,25,3))),"")} | U14: {=IF(M14="Control",INDEX(SR!A:A,1+BIN2DEC(MID($B14,28,2))),"")} | X14: PUSH sr | AC14: 06,0e,16,1e | AD14: 06,0e,16,1e
A15: =DEC2HEX(ROW(A14)-ROW($A$1),3) -> 00D | B15: 01101110011011010000000010101 | F15: {=INDEX(Sources!A:A, 1 + BIN2DEC(LEFT($B15,5)))} -> REG | G15: {=INDEX(Dest1!A:A,1+BIN2DEC(MID($B15,6,5)))} -> OUT | H15: {=INDEX(Source2!A:A,1+BIN2DEC(MID($B15,11,4)))} -> 11 | I15: {=INDEX('D2'!A:A,1+BIN2DEC(MID($B15,16,2)))} -> TMPB | J15: =BIN2DEC(MID($B15,17,1)) -> 0 | K15: =BIN2DEC(MID($B15,18,1)) -> 0 | L15: =BIN2DEC(MID($B15,19,1)) -> 0 | M15: {=INDEX(Types!A:A,1+BIN2DEC(MID($B15,20,2)))} -> Control | N15: {=IF(M15="ALU",INDEX(ALUOps!A:A,1+BIN2DEC(MID($B15,22,5))),"")} | O15: {=IF(M15="ALU",INDEX(TMP!A:A,1+BIN2DEC(MID($B15,27,2))),"")} | P15: =IF(M15="ALU",BIN2DEC(MID($B15,29,1)),"") | Q15: =IF(M15="Jump",BIN2DEC(MID($B15,22,4)),"") | R15: =IF(M15="Jump",15-BIN2DEC(MID($B15,26,4)),"") | S15: {=IF(M15="Control",INDEX(IC!A:A,1+BIN2DEC(MID($B15,21,4))),"")} -> 0 | T15: {=IF(M15="Control",INDEX(EC!A:A,1+BIN2DEC(MID($B15,25,3))),"")} -> 5 | U15: {=IF(M15="Control",INDEX(SR!A:A,1+BIN2DEC(MID($B15,28,2))),"")} -> 1
A16: =DEC2HEX(ROW(A15)-ROW($A$1),3) -> 00E | B16: 01011000110000000010000000000 | F16: {=INDEX(Sources!A:A, 1 + BIN2DEC(LEFT($B16,5)))} -> SIGMA | G16: {=INDEX(Dest1!A:A,1+BIN2DEC(MID($B16,6,5)))} -> SP | H16: {=INDEX(Source2!A:A,1+BIN2DEC(MID($B16,11,4)))} -> -- | I16: {=INDEX('D2'!A:A,1+BIN2DEC(MID($B16,16,2)))} -> 0 | J16: =BIN2DEC(MID($B16,17,1)) -> 0 | K16: =BIN2DEC(MID($B16,18,1)) -> 0 | L16: =BIN2DEC(MID($B16,19,1)) -> 1 | M16: {=INDEX(Types!A:A,1+BIN2DEC(MID($B16,20,2)))} -> Control | N16: {=IF(M16="ALU",INDEX(ALUOps!A:A,1+BIN2DEC(MID($B16,22,5))),"")} | O16: {=IF(M16="ALU",INDEX(TMP!A:A,1+BIN2DEC(MID($B16,27,2))),"")} | P16: =IF(M16="ALU",BIN2DEC(MID($B16,29,1)),"") | Q16: =IF(M16="Jump",BIN2DEC(MID($B16,22,4)),"") | R16: =IF(M16="Jump",15-BIN2DEC(MID($B16,26,4)),"") | S16: {=IF(M16="Control",INDEX(IC!A:A,1+BIN2DEC(MID($B16,21,4))),"")} -> 0 | T16: {=IF(M16="Control",INDEX(EC!A:A,1+BIN2DEC(MID($B16,25,3))),"")} -> 0 | U16: {=IF(M16="Control",INDEX(SR!A:A,1+BIN2DEC(MID($B16,28,2))),"")} -> 0
A17: =DEC2HEX(ROW(A16)-ROW($A$1),3) -> 00F | B17: 00000000000000000000000000000 | G17: {=INDEX(Dest1!A:A,1+BIN2DEC(MID($B17,6,5)))} -> -- | H17: {=INDEX(Source2!A:A,1+BIN2DEC(MID($B17,11,4)))} -> -- | N17: {=IF(M17="ALU",INDEX(ALUOps!A:A,1+BIN2DEC(MID($B17,22,5))),"")} | O17: {=IF(M17="ALU",INDEX(TMP!A:A,1+BIN2DEC(MID($B17,27,2))),"")} | P17: =IF(M17="ALU",BIN2DEC(MID($B17,29,1)),"") | Q17: =IF(M17="Jump",BIN2DEC(MID($B17,22,4)),"") | R17: =IF(M17="Jump",15-BIN2DEC(MID($B17,26,4)),"") | S17: {=IF(M17="Control",INDEX(IC!A:A,1+BIN2DEC(MID($B17,21,4))),"")} | T17: {=IF(M17="Control",INDEX(EC!A:A,1+BIN2DEC(MID($B17,25,3))),"")} | U17: {=IF(M17="Control",INDEX(SR!A:A,1+BIN2DEC(MID($B17,28,2))),"")}
A18: =DEC2HEX(ROW(A17)-ROW($A$1),3) -> 010 | B18: 00111010100000000001101011101 | C18: 00?.00100111.00 | D18: 00? | E18: 00 | F18: {=INDEX(Sources!A:A, 1 + BIN2DEC(LEFT($B18,5)))} -> A | G18: {=INDEX(Dest1!A:A,1+BIN2DEC(MID($B18,6,5)))} -> UNK10 | H18: {=INDEX(Source2!A:A,1+BIN2DEC(MID($B18,11,4)))} -> -- | I18: {=INDEX('D2'!A:A,1+BIN2DEC(MID($B18,16,2)))} -> 0 | J18: =BIN2DEC(MID($B18,17,1)) -> 0 | K18: =BIN2DEC(MID($B18,18,1)) -> 0 | L18: =BIN2DEC(MID($B18,19,1)) -> 0 | M18: {=INDEX(Types!A:A,1+BIN2DEC(MID($B18,20,2)))} -> ALU | N18: {=IF(M18="ALU",INDEX(ALUOps!A:A,1+BIN2DEC(MID($B18,22,5))),"")} -> 11 | O18: {=IF(M18="ALU",INDEX(TMP!A:A,1+BIN2DEC(MID($B18,27,2))),"")} -> 2 | P18: =IF(M18="ALU",BIN2DEC(MID($B18,29,1)),"") -> 1 | Q18: =IF(M18="Jump",BIN2DEC(MID($B18,22,4)),"") | R18: =IF(M18="Jump",15-BIN2DEC(MID($B18,26,4)),"") | S18: {=IF(M18="Control",INDEX(IC!A:A,1+BIN2DEC(MID($B18,21,4))),"")} | T18: {=IF(M18="Control",INDEX(EC!A:A,1+BIN2DEC(MID($B18,25,3))),"")} | U18: {=IF(M18="Control",INDEX(SR!A:A,1+BIN2DEC(MID($B18,28,2))),"")} | X18: DAA | AC18: 27 | AD18: 27
A19: =DEC2HEX(ROW(A18)-ROW($A$1),3) -> 011 | B19: 01010100110000000011111111111 | F19: {=INDEX(Sources!A:A, 1 + BIN2DEC(LEFT($B19,5)))} -> UNK10 | G19: {=INDEX(Dest1!A:A,1+BIN2DEC(MID($B19,6,5)))} -> TMPB | H19: {=INDEX(Source2!A:A,1+BIN2DEC(MID($B19,11,4)))} -> -- | I19: {=INDEX('D2'!A:A,1+BIN2DEC(MID($B19,16,2)))} -> 0 | J19: =BIN2DEC(MID($B19,17,1)) -> 0 | K19: =BIN2DEC(MID($B19,18,1)) -> 0 | L19: =BIN2DEC(MID($B19,19,1)) -> 1 | M19: {=INDEX(Types!A:A,1+BIN2DEC(MID($B19,20,2)))} -> ALU | N19: {=IF(M19="ALU",INDEX(ALUOps!A:A,1+BIN2DEC(MID($B19,22,5))),"")} -> 31 | O19: {=IF(M19="ALU",INDEX(TMP!A:A,1+BIN2DEC(MID($B19,27,2))),"")} -> 3 | P19: =IF(M19="ALU",BIN2DEC(MID($B19,29,1)),"") -> 1 | Q19: =IF(M19="Jump",BIN2DEC(MID($B19,22,4)),"") | R19: =IF(M19="Jump",15-BIN2DEC(MID($B19,26,4)),"") | S19: {=IF(M19="Control",INDEX(IC!A:A,1+BIN2DEC(MID($B19,21,4))),"")} | T19: {=IF(M19="Control",INDEX(EC!A:A,1+BIN2DEC(MID($B19,25,3))),"")} | U19: {=IF(M19="Control",INDEX(SR!A:A,1+BIN2DEC(MID($B19,28,2))),"")}
A20: =DEC2HEX(ROW(A19)-ROW($A$1),3) -> 012 | B20: 01011101111011000100000000000 | F20: {=INDEX(Sources!A:A, 1 + BIN2DEC(LEFT($B20,5)))} -> SIGMA | G20: {=INDEX(Dest1!A:A,1+BIN2DEC(MID($B20,6,5)))} -> UNK23 | H20: {=INDEX(Source2!A:A,1+BIN2DEC(MID($B20,11,4)))} -> 11 | I20: {=INDEX('D2'!A:A,1+BIN2DEC(MID($B20,16,2)))} -> 0 | J20: =BIN2DEC(MID($B20,17,1)) -> 0 | K20: =BIN2DEC(MID($B20,18,1)) -> 1 | L20: =BIN2DEC(MID($B20,19,1)) -> 0 | M20: {=INDEX(Types!A:A,1+BIN2DEC(MID($B20,20,2)))} -> Control | N20: {=IF(M20="ALU",INDEX(ALUOps!A:A,1+BIN2DEC(MID($B20,22,5))),"")} | O20: {=IF(M20="ALU",INDEX(TMP!A:A,1+BIN2DEC(MID($B20,27,2))),"")} | P20: =IF(M20="ALU",BIN2DEC(MID($B20,29,1)),"") | Q20: =IF(M20="Jump",BIN2DEC(MID($B20,22,4)),"") | R20: =IF(M20="Jump",15-BIN2DEC(MID($B20,26,4)),"") | S20: {=IF(M20="Control",INDEX(IC!A:A,1+BIN2DEC(MID($B20,21,4))),"")} -> 0 | T20: {=IF(M20="Control",INDEX(EC!A:A,1+BIN2DEC(MID($B20,25,3))),"")} -> 0 | U20: {=IF(M20="Control",INDEX(SR!A:A,1+BIN2DEC(MID($B20,28,2))),"")} -> 0
A21: =DEC2HEX(ROW(A20)-ROW($A$1),3) -> 013 | B21: 00000000000000000000000000000 | G21: {=INDEX(Dest1!A:A,1+BIN2DEC(MID($B21,6,5)))} -> -- | H21: {=INDEX(Source2!A:A,1+BIN2DEC(MID($B21,11,4)))} -> -- | N21: {=IF(M21="ALU",INDEX(ALUOps!A:A,1+BIN2DEC(MID($B21,22,5))),"")} | O21: {=IF(M21="ALU",INDEX(TMP!A:A,1+BIN2DEC(MID($B21,27,2))),"")} | P21: =IF(M21="ALU",BIN2DEC(MID($B21,29,1)),"") | Q21: =IF(M21="Jump",BIN2DEC(MID($B21,22,4)),"") | R21: =IF(M21="Jump",15-BIN2DEC(MID($B21,26,4)),"") | S21: {=IF(M21="Control",INDEX(IC!A:A,1+BIN2DEC(MID($B21,21,4))),"")} | T21: {=IF(M21="Control",INDEX(EC!A:A,1+BIN2DEC(MID($B21,25,3))),"")} | U21: {=IF(M21="Control",INDEX(SR!A:A,1+BIN2DEC(MID($B21,28,2))),"")}
A22: =DEC2HEX(ROW(A21)-ROW($A$1),3) -> 014 | B22: 00111010100000000001101011101 | C22: 00?.00101111.00 | D22: 00? | E22: 00 | F22: {=INDEX(Sources!A:A, 1 + BIN2DEC(LEFT($B22,5)))} -> A | G22: {=INDEX(Dest1!A:A,1+BIN2DEC(MID($B22,6,5)))} -> UNK10 | H22: {=INDEX(Source2!A:A,1+BIN2DEC(MID($B22,11,4)))} -> -- | I22: {=INDEX('D2'!A:A,1+BIN2DEC(MID($B22,16,2)))} -> 0 | J22: =BIN2DEC(MID($B22,17,1)) -> 0 | K22: =BIN2DEC(MID($B22,18,1)) -> 0 | L22: =BIN2DEC(MID($B22,19,1)) -> 0 | M22: {=INDEX(Types!A:A,1+BIN2DEC(MID($B22,20,2)))} -> ALU | N22: {=IF(M22="ALU",INDEX(ALUOps!A:A,1+BIN2DEC(MID($B22,22,5))),"")} -> 11 | O22: {=IF(M22="ALU",INDEX(TMP!A:A,1+BIN2DEC(MID($B22,27,2))),"")} -> 2 | P22: =IF(M22="ALU",BIN2DEC(MID($B22,29,1)),"") -> 1 | Q22: =IF(M22="Jump",BIN2DEC(MID($B22,22,4)),"") | R22: =IF(M22="Jump",15-BIN2DEC(MID($B22,26,4)),"") | S22: {=IF(M22="Control",INDEX(IC!A:A,1+BIN2DEC(MID($B22,21,4))),"")} | T22: {=IF(M22="Control",INDEX(EC!A:A,1+BIN2DEC(MID($B22,25,3))),"")} | U22: {=IF(M22="Control",INDEX(SR!A:A,1+BIN2DEC(MID($B22,28,2))),"")} | X22: DAS | AC22: 2f | AD22: 2f
A23: =DEC2HEX(ROW(A22)-ROW($A$1),3) -> 015 | B23: 01010100110000000011111010111 | F23: {=INDEX(Sources!A:A, 1 + BIN2DEC(LEFT($B23,5)))} -> UNK10 | G23: {=INDEX(Dest1!A:A,1+BIN2DEC(MID($B23,6,5)))} -> TMPB | H23: {=INDEX(Source2!A:A,1+BIN2DEC(MID($B23,11,4)))} -> -- | I23: {=INDEX('D2'!A:A,1+BIN2DEC(MID($B23,16,2)))} -> 0 | J23: =BIN2DEC(MID($B23,17,1)) -> 0 | K23: =BIN2DEC(MID($B23,18,1)) -> 0 | L23: =BIN2DEC(MID($B23,19,1)) -> 1 | M23: {=INDEX(Types!A:A,1+BIN2DEC(MID($B23,20,2)))} -> ALU | N23: {=IF(M23="ALU",INDEX(ALUOps!A:A,1+BIN2DEC(MID($B23,22,5))),"")} -> 26 | O23: {=IF(M23="ALU",INDEX(TMP!A:A,1+BIN2DEC(MID($B23,27,2))),"")} -> 3 | P23: =IF(M23="ALU",BIN2DEC(MID($B23,29,1)),"") -> 1 | Q23: =IF(M23="Jump",BIN2DEC(MID($B23,22,4)),"") | R23: =IF(M23="Jump",15-BIN2DEC(MID($B23,26,4)),"") | S23: {=IF(M23="Control",INDEX(IC!A:A,1+BIN2DEC(MID($B23,21,4))),"")} | T23: {=IF(M23="Control",INDEX(EC!A:A,1+BIN2DEC(MID($B23,25,3))),"")} | U23: {=IF(M23="Control",INDEX(SR!A:A,1+BIN2DEC(MID($B23,28,2))),"")}
A24: =DEC2HEX(ROW(A23)-ROW($A$1),3) -> 016 | B24: 01011101111011000100000000000 | F24: {=INDEX(Sources!A:A, 1 + BIN2DEC(LEFT($B24,5)))} -> SIGMA | G24: {=INDEX(Dest1!A:A,1+BIN2DEC(MID($B24,6,5)))} -> UNK23 | H24: {=INDEX(Source2!A:A,1+BIN2DEC(MID($B24,11,4)))} -> 11 | I24: {=INDEX('D2'!A:A,1+BIN2DEC(MID($B24,16,2)))} -> 0 | J24: =BIN2DEC(MID($B24,17,1)) -> 0 | K24: =BIN2DEC(MID($B24,18,1)) -> 1 | L24: =BIN2DEC(MID($B24,19,1)) -> 0 | M24: {=INDEX(Types!A:A,1+BIN2DEC(MID($B24,20,2)))} -> Control | N24: {=IF(M24="ALU",INDEX(ALUOps!A:A,1+BIN2DEC(MID($B24,22,5))),"")} | O24: {=IF(M24="ALU",INDEX(TMP!A:A,1+BIN2DEC(MID($B24,27,2))),"")} | P24: =IF(M24="ALU",BIN2DEC(MID($B24,29,1)),"") | Q24: =IF(M24="Jump",BIN2DEC(MID($B24,22,4)),"") | R24: =IF(M24="Jump",15-BIN2DEC(MID($B24,26,4)),"") | S24: {=IF(M24="Control",INDEX(IC!A:A,1+BIN2DEC(MID($B24,21,4))),"")} -> 0 | T24: {=IF(M24="Control",INDEX(EC!A:A,1+BIN2DEC(MID($B24,25,3))),"")} -> 0 | U24: {=IF(M24="Control",INDEX(SR!A:A,1+BIN2DEC(MID($B24,28,2))),"")} -> 0
A25: =DEC2HEX(ROW(A24)-ROW($A$1),3) -> 017 | B25: 00000000000000000000000000000 | G25: {=INDEX(Dest1!A:A,1+BIN2DEC(MID($B25,6,5)))} -> -- | H25: {=INDEX(Source2!A:A,1+BIN2DEC(MID($B25,11,4)))} -> -- | N25: {=IF(M25="ALU",INDEX(ALUOps!A:A,1+BIN2DEC(MID($B25,22,5))),"")} | O25: {=IF(M25="ALU",INDEX(TMP!A:A,1+BIN2DEC(MID($B25,27,2))),"")} | P25: =IF(M25="ALU",BIN2DEC(MID($B25,29,1)),"") | Q25: =IF(M25="Jump",BIN2DEC(MID($B25,22,4)),"") | R25: =IF(M25="Jump",15-BIN2DEC(MID($B25,26,4)),"") | S25: {=IF(M25="Control",INDEX(IC!A:A,1+BIN2DEC(MID($B25,21,4))),"")} | T25: {=IF(M25="Control",INDEX(EC!A:A,1+BIN2DEC(MID($B25,25,3))),"")} | U25: {=IF(M25="Control",INDEX(SR!A:A,1+BIN2DEC(MID($B25,28,2))),"")}
A26: =DEC2HEX(ROW(A25)-ROW($A$1),3) -> 018 | B26: 00111010100000000001101010101 | C26: 00?.00110111.00 | D26: 00? | E26: 00 | F26: {=INDEX(Sources!A:A, 1 + BIN2DEC(LEFT($B26,5)))} -> A | G26: {=INDEX(Dest1!A:A,1+BIN2DEC(MID($B26,6,5)))} -> UNK10 | H26: {=INDEX(Source2!A:A,1+BIN2DEC(MID($B26,11,4)))} -> -- | I26: {=INDEX('D2'!A:A,1+BIN2DEC(MID($B26,16,2)))} -> 0 | J26: =BIN2DEC(MID($B26,17,1)) -> 0 | K26: =BIN2DEC(MID($B26,18,1)) -> 0 | L26: =BIN2DEC(MID($B26,19,1)) -> 0 | M26: {=INDEX(Types!A:A,1+BIN2DEC(MID($B26,20,2)))} -> ALU | N26: {=IF(M26="ALU",INDEX(ALUOps!A:A,1+BIN2DEC(MID($B26,22,5))),"")} -> 10 | O26: {=IF(M26="ALU",INDEX(TMP!A:A,1+BIN2DEC(MID($B26,27,2))),"")} -> 2 | P26: =IF(M26="ALU",BIN2DEC(MID($B26,29,1)),"") -> 1 | Q26: =IF(M26="Jump",BIN2DEC(MID($B26,22,4)),"") | R26: =IF(M26="Jump",15-BIN2DEC(MID($B26,26,4)),"") | S26: {=IF(M26="Control",INDEX(IC!A:A,1+BIN2DEC(MID($B26,21,4))),"")} | T26: {=IF(M26="Control",INDEX(EC!A:A,1+BIN2DEC(MID($B26,25,3))),"")} | U26: {=IF(M26="Control",INDEX(SR!A:A,1+BIN2DEC(MID($B26,28,2))),"")} | X26: AAA | AC26: 37 | AD26: 37
A27: =DEC2HEX(ROW(A26)-ROW($A$1),3) -> 019 | B27: 01010100110000000001111111111 | F27: {=INDEX(Sources!A:A, 1 + BIN2DEC(LEFT($B27,5)))} -> UNK10 | G27: {=INDEX(Dest1!A:A,1+BIN2DEC(MID($B27,6,5)))} -> TMPB | H27: {=INDEX(Source2!A:A,1+BIN2DEC(MID($B27,11,4)))} -> -- | I27: {=INDEX('D2'!A:A,1+BIN2DEC(MID($B27,16,2)))} -> 0 | J27: =BIN2DEC(MID($B27,17,1)) -> 0 | K27: =BIN2DEC(MID($B27,18,1)) -> 0 | L27: =BIN2DEC(MID($B27,19,1)) -> 0 | M27: {=INDEX(Types!A:A,1+BIN2DEC(MID($B27,20,2)))} -> ALU | N27: {=IF(M27="ALU",INDEX(ALUOps!A:A,1+BIN2DEC(MID($B27,22,5))),"")} -> 31 | O27: {=IF(M27="ALU",INDEX(TMP!A:A,1+BIN2DEC(MID($B27,27,2))),"")} -> 3 | P27: =IF(M27="ALU",BIN2DEC(MID($B27,29,1)),"") -> 1 | Q27: =IF(M27="Jump",BIN2DEC(MID($B27,22,4)),"") | R27: =IF(M27="Jump",15-BIN2DEC(MID($B27,26,4)),"") | S27: {=IF(M27="Control",INDEX(IC!A:A,1+BIN2DEC(MID($B27,21,4))),"")} | T27: {=IF(M27="Control",INDEX(EC!A:A,1+BIN2DEC(MID($B27,25,3))),"")} | U27: {=IF(M27="Control",INDEX(SR!A:A,1+BIN2DEC(MID($B27,28,2))),"")}
A28: =DEC2HEX(ROW(A27)-ROW($A$1),3) -> 01A | B28: 01011101111011000101100111101 | F28: {=INDEX(Sources!A:A, 1 + BIN2DEC(LEFT($B28,5)))} -> SIGMA | G28: {=INDEX(Dest1!A:A,1+BIN2DEC(MID($B28,6,5)))} -> UNK23 | H28: {=INDEX(Source2!A:A,1+BIN2DEC(MID($B28,11,4)))} -> 11 | I28: {=INDEX('D2'!A:A,1+BIN2DEC(MID($B28,16,2)))} -> 0 | J28: =BIN2DEC(MID($B28,17,1)) -> 0 | K28: =BIN2DEC(MID($B28,18,1)) -> 1 | L28: =BIN2DEC(MID($B28,19,1)) -> 0 | M28: {=INDEX(Types!A:A,1+BIN2DEC(MID($B28,20,2)))} -> ALU | N28: {=IF(M28="ALU",INDEX(ALUOps!A:A,1+BIN2DEC(MID($B28,22,5))),"")} -> 7 | O28: {=IF(M28="ALU",INDEX(TMP!A:A,1+BIN2DEC(MID($B28,27,2))),"")} -> 2 | P28: =IF(M28="ALU",BIN2DEC(MID($B28,29,1)),"") -> 1 | Q28: =IF(M28="Jump",BIN2DEC(MID($B28,22,4)),"") | R28: =IF(M28="Jump",15-BIN2DEC(MID($B28,26,4)),"") | S28: {=IF(M28="Control",INDEX(IC!A:A,1+BIN2DEC(MID($B28,21,4))),"")} | T28: {=IF(M28="Control",INDEX(EC!A:A,1+BIN2DEC(MID($B28,25,3))),"")} | U28: {=IF(M28="Control",INDEX(SR!A:A,1+BIN2DEC(MID($B28,28,2))),"")}
A29: =DEC2HEX(ROW(A28)-ROW($A$1),3) -> 01B | B29: 01111100100000000001011101010 | F29: {=INDEX(Sources!A:A, 1 + BIN2DEC(LEFT($B29,5)))} -> AH | G29: {=INDEX(Dest1!A:A,1+BIN2DEC(MID($B29,6,5)))} -> TMPA | H29: {=INDEX(Source2!A:A,1+BIN2DEC(MID($B29,11,4)))} -> -- | I29: {=INDEX('D2'!A:A,1+BIN2DEC(MID($B29,16,2)))} -> 0 | J29: =BIN2DEC(MID($B29,17,1)) -> 0 | K29: =BIN2DEC(MID($B29,18,1)) -> 0 | L29: =BIN2DEC(MID($B29,19,1)) -> 0 | M29: {=INDEX(Types!A:A,1+BIN2DEC(MID($B29,20,2)))} -> Jump | N29: {=IF(M29="ALU",INDEX(ALUOps!A:A,1+BIN2DEC(MID($B29,22,5))),"")} | O29: {=IF(M29="ALU",INDEX(TMP!A:A,1+BIN2DEC(MID($B29,27,2))),"")} | P29: =IF(M29="ALU",BIN2DEC(MID($B29,29,1)),"") | Q29: =IF(M29="Jump",BIN2DEC(MID($B29,22,4)),"") -> 14 | R29: =IF(M29="Jump",15-BIN2DEC(MID($B29,26,4)),"") -> 5 | S29: {=IF(M29="Control",INDEX(IC!A:A,1+BIN2DEC(MID($B29,21,4))),"")} | T29: {=IF(M29="Control",INDEX(EC!A:A,1+BIN2DEC(MID($B29,25,3))),"")} | U29: {=IF(M29="Control",INDEX(SR!A:A,1+BIN2DEC(MID($B29,28,2))),"")}
A30: =DEC2HEX(ROW(A29)-ROW($A$1),3) -> 01C | B30: 01011011110000000000000000000 | C30: 00?.0011?111.01 | D30: 00? | E30: 01 | F30: {=INDEX(Sources!A:A, 1 + BIN2DEC(LEFT($B30,5)))} -> SIGMA | G30: {=INDEX(Dest1!A:A,1+BIN2DEC(MID($B30,6,5)))} -> AH | H30: {=INDEX(Source2!A:A,1+BIN2DEC(MID($B30,11,4)))} -> -- | I30: {=INDEX('D2'!A:A,1+BIN2DEC(MID($B30,16,2)))} -> 0 | J30: =BIN2DEC(MID($B30,17,1)) -> 0 | K30: =BIN2DEC(MID($B30,18,1)) -> 0 | L30: =BIN2DEC(MID($B30,19,1)) -> 0 | M30: {=INDEX(Types!A:A,1+BIN2DEC(MID($B30,20,2)))} -> Control | N30: {=IF(M30="ALU",INDEX(ALUOps!A:A,1+BIN2DEC(MID($B30,22,5))),"")} | O30: {=IF(M30="ALU",INDEX(TMP!A:A,1+BIN2DEC(MID($B30,27,2))),"")} | P30: =IF(M30="ALU",BIN2DEC(MID($B30,29,1)),"") | Q30: =IF(M30="Jump",BIN2DEC(MID($B30,22,4)),"") | R30: =IF(M30="Jump",15-BIN2DEC(MID($B30,26,4)),"") | S30: {=IF(M30="Control",INDEX(IC!A:A,1+BIN2DEC(MID($B30,21,4))),"")} -> 0 | T30: {=IF(M30="Control",INDEX(EC!A:A,1+BIN2DEC(MID($B30,25,3))),"")} -> 0 | U30: {=IF(M30="Control",INDEX(SR!A:A,1+BIN2DEC(MID($B30,28,2))),"")} -> 0 | X30: AAA/AAS | AC30: 37,3f | AD30: 37,3f
A31: =DEC2HEX(ROW(A30)-ROW($A$1),3) -> 01D | B31: 00000000000000000010000000000 | F31: {=INDEX(Sources!A:A, 1 + BIN2DEC(LEFT($B31,5)))} -> -- | G31: {=INDEX(Dest1!A:A,1+BIN2DEC(MID($B31,6,5)))} -> -- | H31: {=INDEX(Source2!A:A,1+BIN2DEC(MID($B31,11,4)))} -> -- | I31: {=INDEX('D2'!A:A,1+BIN2DEC(MID($B31,16,2)))} -> 0 | J31: =BIN2DEC(MID($B31,17,1)) -> 0 | K31: =BIN2DEC(MID($B31,18,1)) -> 0 | L31: =BIN2DEC(MID($B31,19,1)) -> 1 | M31: {=INDEX(Types!A:A,1+BIN2DEC(MID($B31,20,2)))} -> Control | N31: {=IF(M31="ALU",INDEX(ALUOps!A:A,1+BIN2DEC(MID($B31,22,5))),"")} | O31: {=IF(M31="ALU",INDEX(TMP!A:A,1+BIN2DEC(MID($B31,27,2))),"")} | P31: =IF(M31="ALU",BIN2DEC(MID($B31,29,1)),"") | Q31: =IF(M31="Jump",BIN2DEC(MID($B31,22,4)),"") | R31: =IF(M31="Jump",15-BIN2DEC(MID($B31,26,4)),"") | S31: {=IF(M31="Control",INDEX(IC!A:A,1+BIN2DEC(MID($B31,21,4))),"")} -> 0 | T31: {=IF(M31="Control",INDEX(EC!A:A,1+BIN2DEC(MID($B31,25,3))),"")} -> 0 | U31: {=IF(M31="Control",INDEX(SR!A:A,1+BIN2DEC(MID($B31,28,2))),"")} -> 0
A32: =DEC2HEX(ROW(A31)-ROW($A$1),3) -> 01E | B32: 00000000000000000000000000000 | G32: {=INDEX(Dest1!A:A,1+BIN2DEC(MID($B32,6,5)))} -> -- | H32: {=INDEX(Source2!A:A,1+BIN2DEC(MID($B32,11,4)))} -> -- | N32: {=IF(M32="ALU",INDEX(ALUOps!A:A,1+BIN2DEC(MID($B32,22,5))),"")} | O32: {=IF(M32="ALU",INDEX(TMP!A:A,1+BIN2DEC(MID($B32,27,2))),"")} | P32: =IF(M32="ALU",BIN2DEC(MID($B32,29,1)),"") | Q32: =IF(M32="Jump",BIN2DEC(MID($B32,22,4)),"") | R32: =IF(M32="Jump",15-BIN2DEC(MID($B32,26,4)),"") | S32: {=IF(M32="Control",INDEX(IC!A:A,1+BIN2DEC(MID($B32,21,4))),"")} | T32: {=IF(M32="Control",INDEX(EC!A:A,1+BIN2DEC(MID($B32,25,3))),"")} | U32: {=IF(M32="Control",INDEX(SR!A:A,1+BIN2DEC(MID($B32,28,2))),"")}
A33: =DEC2HEX(ROW(A32)-ROW($A$1),3) -> 01F | B33: 00000000000000000000000000000 | G33: {=INDEX(Dest1!A:A,1+BIN2DEC(MID($B33,6,5)))} -> -- | H33: {=INDEX(Source2!A:A,1+BIN2DEC(MID($B33,11,4)))} -> -- | N33: {=IF(M33="ALU",INDEX(ALUOps!A:A,1+BIN2DEC(MID($B33,22,5))),"")} | O33: {=IF(M33="ALU",INDEX(TMP!A:A,1+BIN2DEC(MID($B33,27,2))),"")} | P33: =IF(M33="ALU",BIN2DEC(MID($B33,29,1)),"") | Q33: =IF(M33="Jump",BIN2DEC(MID($B33,22,4)),"") | R33: =IF(M33="Jump",15-BIN2DEC(MID($B33,26,4)),"") | S33: {=IF(M33="Control",INDEX(IC!A:A,1+BIN2DEC(MID($B33,21,4))),"")} | T33: {=IF(M33="Control",INDEX(EC!A:A,1+BIN2DEC(MID($B33,25,3))),"")} | U33: {=IF(M33="Control",INDEX(SR!A:A,1+BIN2DEC(MID($B33,28,2))),"")}
A34: =DEC2HEX(ROW(A33)-ROW($A$1),3) -> 020 | B34: 00111010100000000001101010101 | C34: 00?.00111111.00 | D34: 00? | E34: 00 | F34: {=INDEX(Sources!A:A, 1 + BIN2DEC(LEFT($B34,5)))} -> A | G34: {=INDEX(Dest1!A:A,1+BIN2DEC(MID($B34,6,5)))} -> UNK10 | H34: {=INDEX(Source2!A:A,1+BIN2DEC(MID($B34,11,4)))} -> -- | I34: {=INDEX('D2'!A:A,1+BIN2DEC(MID($B34,16,2)))} -> 0 | J34: =BIN2DEC(MID($B34,17,1)) -> 0 | K34: =BIN2DEC(MID($B34,18,1)) -> 0 | L34: =BIN2DEC(MID($B34,19,1)) -> 0 | M34: {=INDEX(Types!A:A,1+BIN2DEC(MID($B34,20,2)))} -> ALU | N34: {=IF(M34="ALU",INDEX(ALUOps!A:A,1+BIN2DEC(MID($B34,22,5))),"")} -> 10 | O34: {=IF(M34="ALU",INDEX(TMP!A:A,1+BIN2DEC(MID($B34,27,2))),"")} -> 2 | P34: =IF(M34="ALU",BIN2DEC(MID($B34,29,1)),"") -> 1 | Q34: =IF(M34="Jump",BIN2DEC(MID($B34,22,4)),"") | R34: =IF(M34="Jump",15-BIN2DEC(MID($B34,26,4)),"") | S34: {=IF(M34="Control",INDEX(IC!A:A,1+BIN2DEC(MID($B34,21,4))),"")} | T34: {=IF(M34="Control",INDEX(EC!A:A,1+BIN2DEC(MID($B34,25,3))),"")} | U34: {=IF(M34="Control",INDEX(SR!A:A,1+BIN2DEC(MID($B34,28,2))),"")} | X34: AAS | AC34: 3f | AD34: 3f
A35: =DEC2HEX(ROW(A34)-ROW($A$1),3) -> 021 | B35: 01010100110000000001111010111 | F35: {=INDEX(Sources!A:A, 1 + BIN2DEC(LEFT($B35,5)))} -> UNK10 | G35: {=INDEX(Dest1!A:A,1+BIN2DEC(MID($B35,6,5)))} -> TMPB | H35: {=INDEX(Source2!A:A,1+BIN2DEC(MID($B35,11,4)))} -> -- | I35: {=INDEX('D2'!A:A,1+BIN2DEC(MID($B35,16,2)))} -> 0 | J35: =BIN2DEC(MID($B35,17,1)) -> 0 | K35: =BIN2DEC(MID($B35,18,1)) -> 0 | L35: =BIN2DEC(MID($B35,19,1)) -> 0 | M35: {=INDEX(Types!A:A,1+BIN2DEC(MID($B35,20,2)))} -> ALU | N35: {=IF(M35="ALU",INDEX(ALUOps!A:A,1+BIN2DEC(MID($B35,22,5))),"")} -> 26 | O35: {=IF(M35="ALU",INDEX(TMP!A:A,1+BIN2DEC(MID($B35,27,2))),"")} -> 3 | P35: =IF(M35="ALU",BIN2DEC(MID($B35,29,1)),"") -> 1 | Q35: =IF(M35="Jump",BIN2DEC(MID($B35,22,4)),"") | R35: =IF(M35="Jump",15-BIN2DEC(MID($B35,26,4)),"") | S35: {=IF(M35="Control",INDEX(IC!A:A,1+BIN2DEC(MID($B35,21,4))),"")} | T35: {=IF(M35="Control",INDEX(EC!A:A,1+BIN2DEC(MID($B35,25,3))),"")} | U35: {=IF(M35="Control",INDEX(SR!A:A,1+BIN2DEC(MID($B35,28,2))),"")}
A36: =DEC2HEX(ROW(A35)-ROW($A$1),3) -> 022 | B36: 01011101111011000101100110101 | F36: {=INDEX(Sources!A:A, 1 + BIN2DEC(LEFT($B36,5)))} -> SIGMA | G36: {=INDEX(Dest1!A:A,1+BIN2DEC(MID($B36,6,5)))} -> UNK23 | H36: {=INDEX(Source2!A:A,1+BIN2DEC(MID($B36,11,4)))} -> 11 | I36: {=INDEX('D2'!A:A,1+BIN2DEC(MID($B36,16,2)))} -> 0 | J36: =BIN2DEC(MID($B36,17,1)) -> 0 | K36: =BIN2DEC(MID($B36,18,1)) -> 1 | L36: =BIN2DEC(MID($B36,19,1)) -> 0 | M36: {=INDEX(Types!A:A,1+BIN2DEC(MID($B36,20,2)))} -> ALU | N36: {=IF(M36="ALU",INDEX(ALUOps!A:A,1+BIN2DEC(MID($B36,22,5))),"")} -> 6 | O36: {=IF(M36="ALU",INDEX(TMP!A:A,1+BIN2DEC(MID($B36,27,2))),"")} -> 2 | P36: =IF(M36="ALU",BIN2DEC(MID($B36,29,1)),"") -> 1 | Q36: =IF(M36="Jump",BIN2DEC(MID($B36,22,4)),"") | R36: =IF(M36="Jump",15-BIN2DEC(MID($B36,26,4)),"") | S36: {=IF(M36="Control",INDEX(IC!A:A,1+BIN2DEC(MID($B36,21,4))),"")} | T36: {=IF(M36="Control",INDEX(EC!A:A,1+BIN2DEC(MID($B36,25,3))),"")} | U36: {=IF(M36="Control",INDEX(SR!A:A,1+BIN2DEC(MID($B36,28,2))),"")}
A37: =DEC2HEX(ROW(A36)-ROW($A$1),3) -> 023 | B37: 01111100100000000001011101010 | F37: {=INDEX(Sources!A:A, 1 + BIN2DEC(LEFT($B37,5)))} -> AH | G37: {=INDEX(Dest1!A:A,1+BIN2DEC(MID($B37,6,5)))} -> TMPA | H37: {=INDEX(Source2!A:A,1+BIN2DEC(MID($B37,11,4)))} -> -- | I37: {=INDEX('D2'!A:A,1+BIN2DEC(MID($B37,16,2)))} -> 0 | J37: =BIN2DEC(MID($B37,17,1)) -> 0 | K37: =BIN2DEC(MID($B37,18,1)) -> 0 | L37: =BIN2DEC(MID($B37,19,1)) -> 0 | M37: {=INDEX(Types!A:A,1+BIN2DEC(MID($B37,20,2)))} -> Jump | N37: {=IF(M37="ALU",INDEX(ALUOps!A:A,1+BIN2DEC(MID($B37,22,5))),"")} | O37: {=IF(M37="ALU",INDEX(TMP!A:A,1+BIN2DEC(MID($B37,27,2))),"")} | P37: =IF(M37="ALU",BIN2DEC(MID($B37,29,1)),"") | Q37: =IF(M37="Jump",BIN2DEC(MID($B37,22,4)),"") -> 14 | R37: =IF(M37="Jump",15-BIN2DEC(MID($B37,26,4)),"") -> 5 | S37: {=IF(M37="Control",INDEX(IC!A:A,1+BIN2DEC(MID($B37,21,4))),"")} | T37: {=IF(M37="Control",INDEX(EC!A:A,1+BIN2DEC(MID($B37,25,3))),"")} | U37: {=IF(M37="Control",INDEX(SR!A:A,1+BIN2DEC(MID($B37,28,2))),"")}
A38: =DEC2HEX(ROW(A37)-ROW($A$1),3) -> 024 | B38: 01100100100000000011101001101 | C38: 00?.0100????.00 | D38: 00? | E38: 00 | F38: {=INDEX(Sources!A:A, 1 + BIN2DEC(LEFT($B38,5)))} -> OPR | G38: {=INDEX(Dest1!A:A,1+BIN2DEC(MID($B38,6,5)))} -> TMPA | H38: {=INDEX(Source2!A:A,1+BIN2DEC(MID($B38,11,4)))} -> -- | I38: {=INDEX('D2'!A:A,1+BIN2DEC(MID($B38,16,2)))} -> 0 | J38: =BIN2DEC(MID($B38,17,1)) -> 0 | K38: =BIN2DEC(MID($B38,18,1)) -> 0 | L38: =BIN2DEC(MID($B38,19,1)) -> 1 | M38: {=INDEX(Types!A:A,1+BIN2DEC(MID($B38,20,2)))} -> ALU | N38: {=IF(M38="ALU",INDEX(ALUOps!A:A,1+BIN2DEC(MID($B38,22,5))),"")} -> 9 | O38: {=IF(M38="ALU",INDEX(TMP!A:A,1+BIN2DEC(MID($B38,27,2))),"")} -> 2 | P38: =IF(M38="ALU",BIN2DEC(MID($B38,29,1)),"") -> 1 | Q38: =IF(M38="Jump",BIN2DEC(MID($B38,22,4)),"") | R38: =IF(M38="Jump",15-BIN2DEC(MID($B38,26,4)),"") | S38: {=IF(M38="Control",INDEX(IC!A:A,1+BIN2DEC(MID($B38,21,4))),"")} | T38: {=IF(M38="Control",INDEX(EC!A:A,1+BIN2DEC(MID($B38,25,3))),"")} | U38: {=IF(M38="Control",INDEX(SR!A:A,1+BIN2DEC(MID($B38,28,2))),"")} | X38: INC/DEC | AC38: 40-4f | AD38: 40,41,42,43,44,45,46,47,48,49,4a,4b,4c,4d,4e,4f
A39: =DEC2HEX(ROW(A38)-ROW($A$1),3) -> 025 | B39: 01011011000000000100000000000 | F39: {=INDEX(Sources!A:A, 1 + BIN2DEC(LEFT($B39,5)))} -> SIGMA | G39: {=INDEX(Dest1!A:A,1+BIN2DEC(MID($B39,6,5)))} -> OPR | H39: {=INDEX(Source2!A:A,1+BIN2DEC(MID($B39,11,4)))} -> -- | I39: {=INDEX('D2'!A:A,1+BIN2DEC(MID($B39,16,2)))} -> 0 | J39: =BIN2DEC(MID($B39,17,1)) -> 0 | K39: =BIN2DEC(MID($B39,18,1)) -> 1 | L39: =BIN2DEC(MID($B39,19,1)) -> 0 | M39: {=INDEX(Types!A:A,1+BIN2DEC(MID($B39,20,2)))} -> Control | N39: {=IF(M39="ALU",INDEX(ALUOps!A:A,1+BIN2DEC(MID($B39,22,5))),"")} | O39: {=IF(M39="ALU",INDEX(TMP!A:A,1+BIN2DEC(MID($B39,27,2))),"")} | P39: =IF(M39="ALU",BIN2DEC(MID($B39,29,1)),"") | Q39: =IF(M39="Jump",BIN2DEC(MID($B39,22,4)),"") | R39: =IF(M39="Jump",15-BIN2DEC(MID($B39,26,4)),"") | S39: {=IF(M39="Control",INDEX(IC!A:A,1+BIN2DEC(MID($B39,21,4))),"")} -> 0 | T39: {=IF(M39="Control",INDEX(EC!A:A,1+BIN2DEC(MID($B39,25,3))),"")} -> 0 | U39: {=IF(M39="Control",INDEX(SR!A:A,1+BIN2DEC(MID($B39,28,2))),"")} -> 0
A40: =DEC2HEX(ROW(A39)-ROW($A$1),3) -> 026 | B40: 00000000000000000000000000000 | G40: {=INDEX(Dest1!A:A,1+BIN2DEC(MID($B40,6,5)))} -> -- | H40: {=INDEX(Source2!A:A,1+BIN2DEC(MID($B40,11,4)))} -> -- | N40: {=IF(M40="ALU",INDEX(ALUOps!A:A,1+BIN2DEC(MID($B40,22,5))),"")} | O40: {=IF(M40="ALU",INDEX(TMP!A:A,1+BIN2DEC(MID($B40,27,2))),"")} | P40: =IF(M40="ALU",BIN2DEC(MID($B40,29,1)),"") | Q40: =IF(M40="Jump",BIN2DEC(MID($B40,22,4)),"") | R40: =IF(M40="Jump",15-BIN2DEC(MID($B40,26,4)),"") | S40: {=IF(M40="Control",INDEX(IC!A:A,1+BIN2DEC(MID($B40,21,4))),"")} | T40: {=IF(M40="Control",INDEX(EC!A:A,1+BIN2DEC(MID($B40,25,3))),"")} | U40: {=IF(M40="Control",INDEX(SR!A:A,1+BIN2DEC(MID($B40,28,2))),"")}
...

Sheet TMP
A1: 0
A2: 1
A3: 2
A4: 3

Sheet SR
A1: 0
A2: 1
A3: 2
A4: 3

Sheet EC
A1: 0
A2: 1
A3: 2
A4: 3
A5: 4
A6: 5
A7: 6
A8: 7

Sheet IC
A1: 0
A2: 1
A3: 2
A4: 3
A5: 4
A6: 5
A7: 6
A8: 7
A9: 8
A10: 9
A11: 10
A12: 11
... A16: 15

Sheet ALUOps
A1: 0
A2: ADJ2
A3: 2
A4: 3
A5: 4
A6: 5
A7: 6
A8: 7
A9: 8
A10: 9
A11: 10
A12: 11
A13: 12
A14: 13
... A32: 31

Sheet D2
A1: 0
A2: 1
A3: TMPB
A4: 3

Sheet Sources
A1: --
A2: UNK1
A3: UNK2
A4: SP
A5: UNK4
A6: UNK5
A7: C
A8: A
A9: REG
A10: UNK9
A11: UNK10
A12: SIGMA
... A32: ES

Sheet Source2
A1: --
A2: 1
A3: 2
A4: 3
A5: 4
A6: 5
A7: 6
A8: 7
A9: 8
A10: 9
A11: Q
A12: 11
... A16: 15

Sheet Dest1
A1: --
A2: UNK1
A3: UNK2
A4: SP
A5: UNK4
A6: UNK5
A7: C
A8: A
A9: UNK8
A10: UNK9
A11: UNK10
A12: UNK11
... A32: ES

Sheet Types
A1: Control | B1: ALU | C1: Control
A2: Control | B2: Jump | C2: Control
A3: Jump | B3: Control | C3: Jump
A4: ALU | B4: Control | C4: ALU
